[32m2024-01-17 11:35:40 +0100[0m - dagster - [34mDEBUG[0m - __ASSET_JOB - f55d5f4d-3b72-44dc-a8d7-5b9c54d89579 - 59439 - LOGS_CAPTURED - Started capturing logs in process (pid: 59439).
[32m2024-01-17 11:35:41 +0100[0m - dagster - [34mDEBUG[0m - __ASSET_JOB - f55d5f4d-3b72-44dc-a8d7-5b9c54d89579 - 59439 - transfers_today_df - STEP_START - Started execution of step "transfers_today_df".
[32m2024-01-17 11:35:42 +0100[0m - dagster - [34mERROR[0m - [31m__ASSET_JOB - f55d5f4d-3b72-44dc-a8d7-5b9c54d89579 - 59439 - transfers_today_df - STEP_FAILURE - Execution of step "transfers_today_df" failed.

dagster._core.errors.DagsterExecutionInterruptedError

Stack Trace:
  File "/Users/ilyapetruhnov/opt/miniconda3/envs/fanareas/lib/python3.10/site-packages/dagster/_core/execution/plan/execute_plan.py", line 286, in dagster_event_sequence_for_step
    for step_event in check.generator(step_events):
  File "/Users/ilyapetruhnov/opt/miniconda3/envs/fanareas/lib/python3.10/site-packages/dagster/_core/execution/plan/execute_step.py", line 487, in core_dagster_event_sequence_for_step
    for user_event in _step_output_error_checked_user_event_sequence(
  File "/Users/ilyapetruhnov/opt/miniconda3/envs/fanareas/lib/python3.10/site-packages/dagster/_core/execution/plan/execute_step.py", line 169, in _step_output_error_checked_user_event_sequence
    for user_event in user_event_sequence:
  File "/Users/ilyapetruhnov/opt/miniconda3/envs/fanareas/lib/python3.10/site-packages/dagster/_core/execution/plan/execute_step.py", line 95, in _process_asset_results_to_events
    for user_event in user_event_sequence:
  File "/Users/ilyapetruhnov/opt/miniconda3/envs/fanareas/lib/python3.10/site-packages/dagster/_core/execution/plan/compute.py", line 212, in execute_core_compute
    for step_output in _yield_compute_results(step_context, inputs, compute_fn, compute_context):
  File "/Users/ilyapetruhnov/opt/miniconda3/envs/fanareas/lib/python3.10/site-packages/dagster/_core/execution/plan/compute.py", line 181, in _yield_compute_results
    for event in iterate_with_context(
  File "/Users/ilyapetruhnov/opt/miniconda3/envs/fanareas/lib/python3.10/site-packages/dagster/_utils/__init__.py", line 467, in iterate_with_context
    next_output = next(iterator)
  File "/Users/ilyapetruhnov/opt/miniconda3/envs/fanareas/lib/python3.10/site-packages/dagster/_core/execution/plan/compute_generator.py", line 131, in _coerce_op_compute_fn_to_iterator
    result = invoke_compute_fn(
  File "/Users/ilyapetruhnov/opt/miniconda3/envs/fanareas/lib/python3.10/site-packages/dagster/_core/execution/plan/compute_generator.py", line 125, in invoke_compute_fn
    return fn(context, **args_to_pass) if context_arg_provided else fn(**args_to_pass)
  File "/Users/ilyapetruhnov/Documents/Projects/fanareas/fanareas/fanareas/assets/assets.py", line 91, in transfers_today_df
    transfers_today_df = fetch_data(url)
  File "/Users/ilyapetruhnov/opt/miniconda3/envs/fanareas/lib/python3.10/site-packages/dagster/_core/definitions/op_definition.py", line 456, in __call__
    return direct_invocation_result(self, *args, **kwargs)
  File "/Users/ilyapetruhnov/opt/miniconda3/envs/fanareas/lib/python3.10/site-packages/dagster/_core/definitions/op_invocation.py", line 197, in direct_invocation_result
    bound_context = (context or build_op_context()).bind(
  File "/Users/ilyapetruhnov/opt/miniconda3/envs/fanareas/lib/python3.10/site-packages/dagster/_core/execution/context/invocation.py", line 782, in build_op_context
    return UnboundOpExecutionContext(
  File "/Users/ilyapetruhnov/opt/miniconda3/envs/fanareas/lib/python3.10/site-packages/dagster/_core/execution/context/invocation.py", line 93, in __init__
    self._instance = self._exit_stack.enter_context(ephemeral_instance_if_missing(instance))
  File "/Users/ilyapetruhnov/opt/miniconda3/envs/fanareas/lib/python3.10/contextlib.py", line 492, in enter_context
    result = _cm_type.__enter__(cm)
  File "/Users/ilyapetruhnov/opt/miniconda3/envs/fanareas/lib/python3.10/contextlib.py", line 135, in __enter__
    return next(self.gen)
  File "/Users/ilyapetruhnov/opt/miniconda3/envs/fanareas/lib/python3.10/site-packages/dagster/_core/execution/api.py", line 292, in ephemeral_instance_if_missing
    with DagsterInstance.ephemeral() as ephemeral_instance:
  File "/Users/ilyapetruhnov/opt/miniconda3/envs/fanareas/lib/python3.10/site-packages/dagster/_core/instance/__init__.py", line 520, in ephemeral
    event_storage=InMemoryEventLogStorage(preload=preload),
  File "/Users/ilyapetruhnov/opt/miniconda3/envs/fanareas/lib/python3.10/site-packages/dagster/_core/storage/event_log/in_memory.py", line 42, in __init__
    self.reindex_events()
  File "/Users/ilyapetruhnov/opt/miniconda3/envs/fanareas/lib/python3.10/site-packages/dagster/_core/storage/event_log/sql_event_log.py", line 684, in reindex_events
    self._apply_migration(migration_name, migration_fn, print_fn, force)
  File "/Users/ilyapetruhnov/opt/miniconda3/envs/fanareas/lib/python3.10/site-packages/dagster/_core/storage/event_log/sql_event_log.py", line 677, in _apply_migration
    self.enable_secondary_index(migration_name)
  File "/Users/ilyapetruhnov/opt/miniconda3/envs/fanareas/lib/python3.10/site-packages/dagster/_core/storage/event_log/sql_event_log.py", line 843, in enable_secondary_index
    conn.execute(query)
  File "/Users/ilyapetruhnov/opt/miniconda3/envs/fanareas/lib/python3.10/site-packages/sqlalchemy/engine/base.py", line 1416, in execute
    return meth(
  File "/Users/ilyapetruhnov/opt/miniconda3/envs/fanareas/lib/python3.10/site-packages/sqlalchemy/sql/elements.py", line 517, in _execute_on_connection
    return connection._execute_clauseelement(
  File "/Users/ilyapetruhnov/opt/miniconda3/envs/fanareas/lib/python3.10/site-packages/sqlalchemy/engine/base.py", line 1639, in _execute_clauseelement
    ret = self._execute_context(
  File "/Users/ilyapetruhnov/opt/miniconda3/envs/fanareas/lib/python3.10/site-packages/sqlalchemy/engine/base.py", line 1848, in _execute_context
    return self._exec_single_context(
  File "/Users/ilyapetruhnov/opt/miniconda3/envs/fanareas/lib/python3.10/site-packages/sqlalchemy/engine/base.py", line 1988, in _exec_single_context
    self._handle_dbapi_exception(
  File "/Users/ilyapetruhnov/opt/miniconda3/envs/fanareas/lib/python3.10/site-packages/sqlalchemy/engine/base.py", line 2347, in _handle_dbapi_exception
    raise exc_info[1].with_traceback(exc_info[2])
  File "/Users/ilyapetruhnov/opt/miniconda3/envs/fanareas/lib/python3.10/site-packages/sqlalchemy/engine/base.py", line 1969, in _exec_single_context
    self.dialect.do_execute(
  File "/Users/ilyapetruhnov/opt/miniconda3/envs/fanareas/lib/python3.10/site-packages/sqlalchemy/engine/default.py", line 922, in do_execute
    cursor.execute(statement, parameters)
  File "/Users/ilyapetruhnov/opt/miniconda3/envs/fanareas/lib/python3.10/site-packages/dagster/_utils/interrupts.py", line 82, in _new_signal_handler
    raise error_cls()
[0m
